<?xml version="1.0"?>
<robot xmlns:xacro="http://www.ros.org/wiki/xacro" >

    <xacro:include filename="inertial_macros.xacro"/>

    <material name="white">
        <color rgba="1 1 1 1" />
    </material>

    <material name="orange">
        <color rgba="1 0.3 0.1 1"/>
    </material>

    <material name="blue">
        <color rgba="0.2 0.2 1 1"/>
    </material>

    <material name="black">
        <color rgba="0 0 0 1"/>
    </material>

    <!-- BASE LINK -->

    <link name="base_link">

    </link>


    <!-- CHASSIS LINK -->

    <joint name="chassis_joint" type="fixed">
        <parent link="base_link"/>
        <child link="chassis"/>
        <origin xyz="-0.1 0 0"/>
    </joint>

    <link name="chassis">
        <visual>
            <origin 
            xyz="0 0 0"
            rpy="0 0 0" />
            
            <geometry>
        	<mesh
          	  filename="package://my_bot/meshes/base_link.STL" />
            </geometry>
            <material name="white"/>
        </visual>
    <collision>
      <origin
        xyz="0 0 0"
        rpy="0 0 0" />
      <geometry>
        <mesh
          filename="package://my_bot/meshes/base_link.STL" />
      </geometry>
    </collision>
        <xacro:inertial_box mass="0.40974" x="0.3" y="0.3" z="0.15">
            <origin xyz="0.0023405 -0.00043339 0.022777" rpy="0 0 0"/>
        </xacro:inertial_box>
    </link>
    
    <gazebo reference="chassis">
        <material>Gazebo/Yellow</material>
    </gazebo>
    
    <!-- LEFT WHEEL LINK -->

    <joint name="left_wheel_joint" type="continuous">
        <parent link="base_link"/>
        <child link="left_wheel"/>
    	<origin
      	xyz="-0.0588 0.0667 0.014"
      	rpy="-1.5708 0 0" />
        <axis xyz="0 0 1"/>
    </joint>

    <link name="left_wheel">
    <visual>
      <origin
        xyz="0 0 0"
        rpy="0 0 0" />
      <geometry>
        <mesh
          filename="package://my_bot/meshes/left_wheel.STL" />
      </geometry>
      <material
        name="black">
      </material>
    </visual>
    <collision>
      <origin
        xyz="0 0 0"
        rpy="0 0 0" />
      <geometry>
        <mesh
          filename="package://my_bot/meshes/left_wheel.STL" />
      </geometry>
    </collision>
        <xacro:inertial_cylinder mass="0.1" length="0.04" radius="0.05">
            <origin xyz="0 0 0" rpy="0 0 0"/>
        </xacro:inertial_cylinder>
    </link>

    <gazebo reference="left_wheel">
        <material>Gazebo/Black</material>
    </gazebo>

    <!-- RIGHT WHEEL LINK -->

    <joint name="right_wheel_joint" type="continuous">
        <parent link="base_link"/>
        <child link="right_wheel"/>
        <origin xyz="-0.058826 -0.0667 0.014" rpy="${pi/2} 0 0" />
        <axis xyz="0 0 -1"/>
    </joint>

    <link name="right_wheel">
    <visual>
      <origin
        xyz="0 0 0"
        rpy="0 0 0" />
      <geometry>
        <mesh
          filename="package://my_bot/meshes/right_wheel.STL" />
      </geometry>
      <material
        name="black">
      </material>
    </visual>
    <collision>
      <origin
        xyz="0 0 0"
        rpy="0 0 0" />
      <geometry>
        <mesh
          filename="package://my_bot/meshes/right_wheel.STL" />
      </geometry>
    </collision>
        <xacro:inertial_cylinder mass="0.031032" length="0.04" radius="0.05">
            <origin xyz="0 0 0" rpy="0 0 0"/>
        </xacro:inertial_cylinder>
    </link>    

    <gazebo reference="right_wheel">
        <material>Gazebo/Blue</material>
    </gazebo>

</robot>
